Workbook

Sheet Matriz_DD_Unificada
A1: # item | B1: Dominio | C1: Subdominio | D1: Requerimiento | E1: Detalle del requerimiento | F1: Artículo / Ítem / Lugar | G1: Normativa | H1: Normativa específica / Fuente | I1: Qué se debe realizar / Documento-Control-Evidencia | J1: Valor cumplimiento (0, 0.5, 1, N/A) | K1: Estado automático | L1: Evidencia levantada | M1: Brecha / observación | N1: Responsable sugerido | O1: Prioridad | P1: Periodicidad / Plazo | Q1: Cruce / equivalencia normativa | R1: Revisión exhaustiva DD | S1: Control ISO/IEC 27001:2022 asociado | T1: Criterio de decisión | U1: Acción sugerida para cierre | V1: Plazo sugerido de atención | W1: Peso de atención | X1: Fase sugerida del plan
A2: 1 | B2: Contexto y alcance | C2: Aplicabilidad normativa | D2: Determinar aplicabilidad SB/SEPS por entidad, servicio y régimen | E2: Identificar si la entidad está controlada por SB, SEPS o ambas; para SEPS, definir segmento/régimen (general, especial o simplificado) y tipo de servicio auxiliar aplicable. | F2: SEPS Art. 1-3; SB Art. 1 | G2: Ambas | H2: SEPS Res. 2022-002; SB Libro I, Título IX, Cap. V | I2: Matriz de aplicabilidad normativa, acta de validación con Legal/Compliance, alcance por empresa y servicio, identificación de régimen SEPS y alcance SB. | J2: 1 | K2: =IF(TRIM(J2&"")="","Por evaluar",IF(UPPER(TRIM(J2&""))="N/A","No aplica",IF(OR(J2=1,J2="1"),"Cumple",IF(OR(J2=0.5,J2="0.5"),"Parcial",IF(OR(J2=0,J2="0"),"No cumple","Revisar valor"))))) -> Cumple | N2: Legal / Cumplimiento / CISO | O2: Alta | P2: Inicial y ante cambio regulatorio o de servicio | Q2: Base para definir qué filas aplican y evitar falsos incumplimientos. | R2: R1 normativa + R2 anexos + R3 cruce | S2: Cl. 4.1, 4.2, 4.3; A.5.31 Requisitos legales, estatutarios, regulatorios y contractuales | T2: =IF(K2="Cumple","Mantener / evidenciar",IF(K2="Parcial","Cerrar brecha parcial",IF(K2="No cumple","Implementar control",IF(K2="No aplica","Sin acción","Levantar evidencia")))) -> Mantener / evidenciar | U2: =IF(K2="Cumple","Mantener evidencia y revisión periódica",IF(K2="No aplica","Documentar justificación de no aplicabilidad",IF(K2="Por evaluar","Levantar evidencia y confirmar aplicabilidad",IF(K2="Parcial","Completar documentación/control y validar efectividad",IF(K2="No cumple","Diseñar, aprobar e implementar control requerido","Corregir valor de cumplimiento"))))) -> Mantener evidencia y revisión periódica | V2: =IF(K2="No cumple",IF(O2="Alta","0-30 días",IF(O2="Media","31-60 días","61-90 días")),IF(K2="Parcial",IF(O2="Alta","0-45 días",IF(O2="Media","31-75 días","61-120 días")),IF(K2="Por evaluar",IF(O2="Alta","0-15 días","0-30 días"),IF(K2="Cumple","Revisión periódica","No aplica")))) -> Revisión periódica | W2: =IF(K2="No cumple",IF(O2="Alta",3,IF(O2="Media",2,1)),IF(K2="Parcial",IF(O2="Alta",2,IF(O2="Media",1.5,1)),IF(K2="Por evaluar",IF(O2="Alta",1.5,IF(O2="Media",1,0.5)),0))) -> 0 | X2: =IF(K2="No aplica","No aplica",IF(K2="Cumple","Mantenimiento",IF(K2="Por evaluar","Fase 0 - Evidencia/aplicabilidad",IF(OR(B2="Gobernanza",B2="SGSI",B2="Contexto y alcance"),"Fase 1 - Gobierno y SGSI",IF(OR(B2="Riesgos",B2="Procesos",B2="Personas"),"Fase 2 - Riesgos y operación",IF(OR(B2="Terceros",B2="Continuidad"),"Fase 3 - Continuidad y terceros",IF(OR(B2="Tecnología",B2="Accesos",B2="Ciberseguridad",B2="Vulnerabilidades",B2="Incidentes",B2="Monitoreo"),"Fase 4 - Controles técnicos","Fase 5 - Canales y datos"))))))) -> Mantenimiento
A3: 2 | B3: Contexto y alcance | C3: Objeto de seguridad | D3: Preservar confidencialidad, integridad y disponibilidad de activos e información | E3: El programa debe proteger información y activos de información, incluyendo datos físicos, digitales, infraestructura, servicios, software, hardware y terceros. | F3: SEPS Art. 2 y 4; SB Art. 2 núm. 50; SB Art. 24 | G3: Ambas | H3: SEPS Res. 2022-002; SB Riesgo Operativo | I3: Declaración formal del objetivo del SGSI, política de seguridad de la información y alcance documentado de activos, servicios y procesos. | J3: 0.5 | K3: =IF(TRIM(J3&"")="","Por evaluar",IF(UPPER(TRIM(J3&""))="N/A","No aplica",IF(OR(J3=1,J3="1"),"Cumple",IF(OR(J3=0.5,J3="0.5"),"Parcial",IF(OR(J3=0,J3="0"),"No cumple","Revisar valor"))))) -> Parcial | M3: Procesos pendiente, no se entrega desde el área de procesos | N3: CISO | O3: Alta | P3: Anual | Q3: CID como principio común de ambas normas. | R3: R1 normativa + R2 anexos + R3 cruce | S3: Cl. 5.2, 6.2; A.5.1 Políticas de SI; A.5.9 Inventario de activos; A.5.12 Clasificación de la información | T3: =IF(K3="Cumple","Mantener / evidenciar",IF(K3="Parcial","Cerrar brecha parcial",IF(K3="No cumple","Implementar control",IF(K3="No aplica","Sin acción","Levantar evidencia")))) -> Cerrar brecha parcial | U3: =IF(K3="Cumple","Mantener evidencia y revisión periódica",IF(K3="No aplica","Documentar justificación de no aplicabilidad",IF(K3="Por evaluar","Levantar evidencia y confirmar aplicabilidad",IF(K3="Parcial","Completar documentación/control y validar efectividad",IF(K3="No cumple","Diseñar, aprobar e implementar control requerido","Corregir valor de cumplimiento"))))) -> Completar documentación/control y validar efectividad | V3: =IF(K3="No cumple",IF(O3="Alta","0-30 días",IF(O3="Media","31-60 días","61-90 días")),IF(K3="Parcial",IF(O3="Alta","0-45 días",IF(O3="Media","31-75 días","61-120 días")),IF(K3="Por evaluar",IF(O3="Alta","0-15 días","0-30 días"),IF(K3="Cumple","Revisión periódica","No aplica")))) -> 0-45 días | W3: =IF(K3="No cumple",IF(O3="Alta",3,IF(O3="Media",2,1)),IF(K3="Parcial",IF(O3="Alta",2,IF(O3="Media",1.5,1)),IF(K3="Por evaluar",IF(O3="Alta",1.5,IF(O3="Media",1,0.5)),0))) -> 2 | X3: =IF(K3="No aplica","No aplica",IF(K3="Cumple","Mantenimiento",IF(K3="Por evaluar","Fase 0 - Evidencia/aplicabilidad",IF(OR(B3="Gobernanza",B3="SGSI",B3="Contexto y alcance"),"Fase 1 - Gobierno y SGSI",IF(OR(B3="Riesgos",B3="Procesos",B3="Personas"),"Fase 2 - Riesgos y operación",IF(OR(B3="Terceros",B3="Continuidad"),"Fase 3 - Continuidad y terceros",IF(OR(B3="Tecnología",B3="Accesos",B3="Ciberseguridad",B3="Vulnerabilidades",B3="Incidentes",B3="Monitoreo"),"Fase 4 - Controles técnicos","Fase 5 - Canales y datos"))))))) -> Fase 1 - Gobierno y SGSI
A4: 3 | B4: Contexto y alcance | C4: Alcance SGSI | D4: Definir alcance del SGSI | E4: El alcance debe considerar tipos de información, procesos críticos/agregadores, personas, unidades, infraestructura tecnológica, ubicaciones físicas y relaciones con terceros que acceden a información crítica o sensible. | F4: SEPS Art. 10; SB Art. 25 núm. 1 | G4: Ambas | H4: SEPS Art. 10; SB Art. 25 | I4: Documento de alcance del SGSI aprobado, mapa de procesos y activos dentro/fuera de alcance, justificación de exclusiones. | J4: 1 | K4: =IF(TRIM(J4&"")="","Por evaluar",IF(UPPER(TRIM(J4&""))="N/A","No aplica",IF(OR(J4=1,J4="1"),"Cumple",IF(OR(J4=0.5,J4="0.5"),"Parcial",IF(OR(J4=0,J4="0"),"No cumple","Revisar valor"))))) -> Cumple | N4: CISO / Dueños de procesos | O4: Alta | P4: Anual o ante cambios | Q4: Requerimiento homologado SEPS-SB. | R4: R1 normativa + R2 anexos + R3 cruce | S4: Cl. 4.3, 4.4; A.5.9 Inventario de activos; A.5.12 Clasificación; A.5.19 Relación con proveedores | T4: =IF(K4="Cumple","Mantener / evidenciar",IF(K4="Parcial","Cerrar brecha parcial",IF(K4="No cumple","Implementar control",IF(K4="No aplica","Sin acción","Levantar evidencia")))) -> Mantener / evidenciar | U4: =IF(K4="Cumple","Mantener evidencia y revisión periódica",IF(K4="No aplica","Documentar justificación de no aplicabilidad",IF(K4="Por evaluar","Levantar evidencia y confirmar aplicabilidad",IF(K4="Parcial","Completar documentación/control y validar efectividad",IF(K4="No cumple","Diseñar, aprobar e implementar control requerido","Corregir valor de cumplimiento"))))) -> Mantener evidencia y revisión periódica | V4: =IF(K4="No cumple",IF(O4="Alta","0-30 días",IF(O4="Media","31-60 días","61-90 días")),IF(K4="Parcial",IF(O4="Alta","0-45 días",IF(O4="Media","31-75 días","61-120 días")),IF(K4="Por evaluar",IF(O4="Alta","0-15 días","0-30 días"),IF(K4="Cumple","Revisión periódica","No aplica")))) -> Revisión periódica | W4: =IF(K4="No cumple",IF(O4="Alta",3,IF(O4="Media",2,1)),IF(K4="Parcial",IF(O4="Alta",2,IF(O4="Media",1.5,1)),IF(K4="Por evaluar",IF(O4="Alta",1.5,IF(O4="Media",1,0.5)),0))) -> 0 | X4: =IF(K4="No aplica","No aplica",IF(K4="Cumple","Mantenimiento",IF(K4="Por evaluar","Fase 0 - Evidencia/aplicabilidad",IF(OR(B4="Gobernanza",B4="SGSI",B4="Contexto y alcance"),"Fase 1 - Gobierno y SGSI",IF(OR(B4="Riesgos",B4="Procesos",B4="Personas"),"Fase 2 - Riesgos y operación",IF(OR(B4="Terceros",B4="Continuidad"),"Fase 3 - Continuidad y terceros",IF(OR(B4="Tecnología",B4="Accesos",B4="Ciberseguridad",B4="Vulnerabilidades",B4="Incidentes",B4="Monitoreo"),"Fase 4 - Controles técnicos","Fase 5 - Canales y datos"))))))) -> Mantenimiento
A5: 4 | B5: Contexto y alcance | C5: Normas de referencia | D5: Adoptar estándares reconocidos para SGSI, controles, continuidad y riesgos | E5: SEPS refiere ISO/IEC 27000 y controles ISO/IEC 27002; SB refiere ISO/IEC 27000, buenas prácticas internacionales de ciberseguridad y continuidad basada en ISO 22301. | F5: SEPS Art. 10-11; SB Art. 18, 24, 25, 26 | G5: Ambas | H5: SEPS y SB | I5: Mapa normativo interno que relacione ISO 27001/27002, ISO 22301, NIST/CSF u otro marco adoptado, con los requisitos SB/SEPS. | J5: 1 | K5: =IF(TRIM(J5&"")="","Por evaluar",IF(UPPER(TRIM(J5&""))="N/A","No aplica",IF(OR(J5=1,J5="1"),"Cumple",IF(OR(J5=0.5,J5="0.5"),"Parcial",IF(OR(J5=0,J5="0"),"No cumple","Revisar valor"))))) -> Cumple | M5: ISO 27001, NIST, CIS controls | N5: CISO / Riesgos / Continuidad | O5: Media | P5: Anual | Q5: Permite evidenciar criterio técnico de control. | R5: R1 normativa + R2 anexos + R3 cruce | S5: Cl. 6.1, 7.5; A.5.31 Requisitos regulatorios; A.5.36 Cumplimiento de políticas y estándares | T5: =IF(K5="Cumple","Mantener / evidenciar",IF(K5="Parcial","Cerrar brecha parcial",IF(K5="No cumple","Implementar control",IF(K5="No aplica","Sin acción","Levantar evidencia")))) -> Mantener / evidenciar | U5: =IF(K5="Cumple","Mantener evidencia y revisión periódica",IF(K5="No aplica","Documentar justificación de no aplicabilidad",IF(K5="Por evaluar","Levantar evidencia y confirmar aplicabilidad",IF(K5="Parcial","Completar documentación/control y validar efectividad",IF(K5="No cumple","Diseñar, aprobar e implementar control requerido","Corregir valor de cumplimiento"))))) -> Mantener evidencia y revisión periódica | V5: =IF(K5="No cumple",IF(O5="Alta","0-30 días",IF(O5="Media","31-60 días","61-90 días")),IF(K5="Parcial",IF(O5="Alta","0-45 días",IF(O5="Media","31-75 días","61-120 días")),IF(K5="Por evaluar",IF(O5="Alta","0-15 días","0-30 días"),IF(K5="Cumple","Revisión periódica","No aplica")))) -> Revisión periódica | W5: =IF(K5="No cumple",IF(O5="Alta",3,IF(O5="Media",2,1)),IF(K5="Parcial",IF(O5="Alta",2,IF(O5="Media",1.5,1)),IF(K5="Por evaluar",IF(O5="Alta",1.5,IF(O5="Media",1,0.5)),0))) -> 0 | X5: =IF(K5="No aplica","No aplica",IF(K5="Cumple","Mantenimiento",IF(K5="Por evaluar","Fase 0 - Evidencia/aplicabilidad",IF(OR(B5="Gobernanza",B5="SGSI",B5="Contexto y alcance"),"Fase 1 - Gobierno y SGSI",IF(OR(B5="Riesgos",B5="Procesos",B5="Personas"),"Fase 2 - Riesgos y operación",IF(OR(B5="Terceros",B5="Continuidad"),"Fase 3 - Continuidad y terceros",IF(OR(B5="Tecnología",B5="Accesos",B5="Ciberseguridad",B5="Vulnerabilidades",B5="Incidentes",B5="Monitoreo"),"Fase 4 - Controles técnicos","Fase 5 - Canales y datos"))))))) -> Mantenimiento
A6: 5 | B6: Gobernanza | C6: Órgano de gobierno | D6: Aprobación formal por Directorio/Consejo | E6: El órgano de gobierno debe aprobar planes, políticas, recursos, roles, responsabilidades, capacitación y gestión de riesgos de seguridad de la información. | F6: SEPS Art. 12, 20, 26; SB Art. 1, 24, 25 | G6: Ambas | H6: SEPS capítulos II-IV; SB Art. 24-25 | I6: Actas de Directorio/Consejo, resoluciones de aprobación, versiones controladas de PESI, políticas, plan de recursos, plan de riesgos y plan de capacitación. | J6: 0.5 | K6: =IF(TRIM(J6&"")="","Por evaluar",IF(UPPER(TRIM(J6&""))="N/A","No aplica",IF(OR(J6=1,J6="1"),"Cumple",IF(OR(J6=0.5,J6="0.5"),"Parcial",IF(OR(J6=0,J6="0"),"No cumple","Revisar valor"))))) -> Parcial | M6: PESI Plan de recursos y riesgos no se tiene Plan de capacitación SI | N6: Directorio / Consejo / Gerencia General | O6: Alta | P6: Según calendario de comités y aprobación anual | Q6: Requisito de gobierno común. | R6: R1 normativa + R2 anexos + R3 cruce | S6: Cl. 5.1, 5.2, 5.3, 6.2; A.5.1 Políticas; A.5.2 Roles y responsabilidades; A.5.36 Cumplimiento | T6: =IF(K6="Cumple","Mantener / evidenciar",IF(K6="Parcial","Cerrar brecha parcial",IF(K6="No cumple","Implementar control",IF(K6="No aplica","Sin acción","Levantar evidencia")))) -> Cerrar brecha parcial | U6: =IF(K6="Cumple","Mantener evidencia y revisión periódica",IF(K6="No aplica","Documentar justificación de no aplicabilidad",IF(K6="Por evaluar","Levantar evidencia y confirmar aplicabilidad",IF(K6="Parcial","Completar documentación/control y validar efectividad",IF(K6="No cumple","Diseñar, aprobar e implementar control requerido","Corregir valor de cumplimiento"))))) -> Completar documentación/control y validar efectividad | V6: =IF(K6="No cumple",IF(O6="Alta","0-30 días",IF(O6="Media","31-60 días","61-90 días")),IF(K6="Parcial",IF(O6="Alta","0-45 días",IF(O6="Media","31-75 días","61-120 días")),IF(K6="Por evaluar",IF(O6="Alta","0-15 días","0-30 días"),IF(K6="Cumple","Revisión periódica","No aplica")))) -> 0-45 días | W6: =IF(K6="No cumple",IF(O6="Alta",3,IF(O6="Media",2,1)),IF(K6="Parcial",IF(O6="Alta",2,IF(O6="Media",1.5,1)),IF(K6="Por evaluar",IF(O6="Alta",1.5,IF(O6="Media",1,0.5)),0))) -> 2 | X6: =IF(K6="No aplica","No aplica",IF(K6="Cumple","Mantenimiento",IF(K6="Por evaluar","Fase 0 - Evidencia/aplicabilidad",IF(OR(B6="Gobernanza",B6="SGSI",B6="Contexto y alcance"),"Fase 1 - Gobierno y SGSI",IF(OR(B6="Riesgos",B6="Procesos",B6="Personas"),"Fase 2 - Riesgos y operación",IF(OR(B6="Terceros",B6="Continuidad"),"Fase 3 - Continuidad y terceros",IF(OR(B6="Tecnología",B6="Accesos",B6="Ciberseguridad",B6="Vulnerabilidades",B6="Incidentes",B6="Monitoreo"),"Fase 4 - Controles técnicos","Fase 5 - Canales y datos"))))))) -> Fase 1 - Gobierno y SGSI
A7: 6 | B7: Gobernanza | C7: Comité de Seguridad | D7: Conformar Comité de Seguridad de la Información | E7: Debe existir un CSI con participación de gobierno, gerencia, riesgos, tecnología y seguridad; en SEPS el presidente del Comité de Administración Integral de Riesgos preside para régimen general/especial; en SB lo preside un miembro del Directorio. | F7: SEPS Art. 6, 15; SB Art. 24 | G7: Ambas | H7: SEPS Art. 6 y 15; SB Art. 24 | I7: Resolución de conformación, reglamento del comité, nómina de miembros titulares, cargos no delegables cuando aplique, matriz de roles y voto/voz. | J7: 1 | K7: =IF(TRIM(J7&"")="","Por evaluar",IF(UPPER(TRIM(J7&""))="N/A","No aplica",IF(OR(J7=1,J7="1"),"Cumple",IF(OR(J7=0.5,J7="0.5"),"Parcial",IF(OR(J7=0,J7="0"),"No cumple","Revisar valor"))))) -> Cumple | N7: Gerencia General / Directorio / CISO | O7: Alta | P7: Conformación inicial y actualización por cambios | Q7: Aplicar criterio más exigente si la entidad está bajo SB. | R7: R1 normativa + R2 anexos + R3 cruce | S7: Cl. 5.3; A.5.2 Roles y responsabilidades; A.5.4 Responsabilidades de la dirección; A.5.35 Revisión independiente | T7: =IF(K7="Cumple","Mantener / evidenciar",IF(K7="Parcial","Cerrar brecha parcial",IF(K7="No cumple","Implementar control",IF(K7="No aplica","Sin acción","Levantar evidencia")))) -> Mantener / evidenciar | U7: =IF(K7="Cumple","Mantener evidencia y revisión periódica",IF(K7="No aplica","Documentar justificación de no aplicabilidad",IF(K7="Por evaluar","Levantar evidencia y confirmar aplicabilidad",IF(K7="Parcial","Completar documentación/control y validar efectividad",IF(K7="No cumple","Diseñar, aprobar e implementar control requerido","Corregir valor de cumplimiento"))))) -> Mantener evidencia y revisión periódica | V7: =IF(K7="No cumple",IF(O7="Alta","0-30 días",IF(O7="Media","31-60 días","61-90 días")),IF(K7="Parcial",IF(O7="Alta","0-45 días",IF(O7="Media","31-75 días","61-120 días")),IF(K7="Por evaluar",IF(O7="Alta","0-15 días","0-30 días"),IF(K7="Cumple","Revisión periódica","No aplica")))) -> Revisión periódica | W7: =IF(K7="No cumple",IF(O7="Alta",3,IF(O7="Media",2,1)),IF(K7="Parcial",IF(O7="Alta",2,IF(O7="Media",1.5,1)),IF(K7="Por evaluar",IF(O7="Alta",1.5,IF(O7="Media",1,0.5)),0))) -> 0 | X7: =IF(K7="No aplica","No aplica",IF(K7="Cumple","Mantenimiento",IF(K7="Por evaluar","Fase 0 - Evidencia/aplicabilidad",IF(OR(B7="Gobernanza",B7="SGSI",B7="Contexto y alcance"),"Fase 1 - Gobierno y SGSI",IF(OR(B7="Riesgos",B7="Procesos",B7="Personas"),"Fase 2 - Riesgos y operación",IF(OR(B7="Terceros",B7="Continuidad"),"Fase 3 - Continuidad y terceros",IF(OR(B7="Tecnología",B7="Accesos",B7="Ciberseguridad",B7="Vulnerabilidades",B7="Incidentes",B7="Monitoreo"),"Fase 4 - Controles técnicos","Fase 5 - Canales y datos"))))))) -> Mantenimiento
A8: 7 | B8: Gobernanza | C8: Sesiones CSI | D8: Sesionar, documentar y custodiar actas del CSI | E8: SEPS exige sesiones ordinarias al menos dos veces al año en régimen general; SB exige reuniones al menos trimestrales y reporte directo al Directorio/Alta Gerencia/CAIR. | F8: SEPS Art. 7; SB Art. 24 | G8: Ambas | H8: SEPS Art. 7; SB Art. 24 | I8: Calendario anual de sesiones, convocatorias, quórum, actas numeradas y firmadas, matriz de compromisos y seguimiento. | J8: 1 | K8: =IF(TRIM(J8&"")="","Por evaluar",IF(UPPER(TRIM(J8&""))="N/A","No aplica",IF(OR(J8=1,J8="1"),"Cumple",IF(OR(J8=0.5,J8="0.5"),"Parcial",IF(OR(J8=0,J8="0"),"No cumple","Revisar valor"))))) -> Cumple | N8: Presidente CSI / Secretario CSI | O8: Alta | P8: Trimestral si aplica SB; mínimo semestral si solo SEPS general/especial | Q8: Criterio más estricto: trimestral. | R8: R1 normativa + R2 anexos + R3 cruce | S8: Cl. 9.3; A.5.35 Revisión independiente; A.5.36 Cumplimiento; A.5.37 Procedimientos operativos documentados | T8: =IF(K8="Cumple","Mantener / evidenciar",IF(K8="Parcial","Cerrar brecha parcial",IF(K8="No cumple","Implementar control",IF(K8="No aplica","Sin acción","Levantar evidencia")))) -> Mantener / evidenciar | U8: =IF(K8="Cumple","Mantener evidencia y revisión periódica",IF(K8="No aplica","Documentar justificación de no aplicabilidad",IF(K8="Por evaluar","Levantar evidencia y confirmar aplicabilidad",IF(K8="Parcial","Completar documentación/control y validar efectividad",IF(K8="No cumple","Diseñar, aprobar e implementar control requerido","Corregir valor de cumplimiento"))))) -> Mantener evidencia y revisión periódica | V8: =IF(K8="No cumple",IF(O8="Alta","0-30 días",IF(O8="Media","31-60 días","61-90 días")),IF(K8="Parcial",IF(O8="Alta","0-45 días",IF(O8="Media","31-75 días","61-120 días")),IF(K8="Por evaluar",IF(O8="Alta","0-15 días","0-30 días"),IF(K8="Cumple","Revisión periódica","No aplica")))) -> Revisión periódica | W8: =IF(K8="No cumple",IF(O8="Alta",3,IF(O8="Media",2,1)),IF(K8="Parcial",IF(O8="Alta",2,IF(O8="Media",1.5,1)),IF(K8="Por evaluar",IF(O8="Alta",1.5,IF(O8="Media",1,0.5)),0))) -> 0 | X8: =IF(K8="No aplica","No aplica",IF(K8="Cumple","Mantenimiento",IF(K8="Por evaluar","Fase 0 - Evidencia/aplicabilidad",IF(OR(B8="Gobernanza",B8="SGSI",B8="Contexto y alcance"),"Fase 1 - Gobierno y SGSI",IF(OR(B8="Riesgos",B8="Procesos",B8="Personas"),"Fase 2 - Riesgos y operación",IF(OR(B8="Terceros",B8="Continuidad"),"Fase 3 - Continuidad y terceros",IF(OR(B8="Tecnología",B8="Accesos",B8="Ciberseguridad",B8="Vulnerabilidades",B8="Incidentes",B8="Monitoreo"),"Fase 4 - Controles técnicos","Fase 5 - Canales y datos"))))))) -> Mantenimiento
A9: 8 | B9: Gobernanza | C9: Reglamento CSI | D9: Expedir reglamento del Comité de Seguridad | E9: SB exige reglamento con objetivo, funciones y responsabilidades; SEPS exige estructura y responsabilidades del comité, por lo que conviene formalizarlo también para SEPS. | F9: SB Art. 24; SEPS Art. 6-7 | G9: Ambas | H9: SB Art. 24; SEPS Art. 6-7 | I9: Reglamento del CSI aprobado, objetivo, funciones, miembros, quórum, voto, frecuencia, reportes, custodia de actas y flujo de escalamiento. | J9: 1 | K9: =IF(TRIM(J9&"")="","Por evaluar",IF(UPPER(TRIM(J9&""))="N/A","No aplica",IF(OR(J9=1,J9="1"),"Cumple",IF(OR(J9=0.5,J9="0.5"),"Parcial",IF(OR(J9=0,J9="0"),"No cumple","Revisar valor"))))) -> Cumple | N9: CISO / Secretaría CSI | O9: Alta | P9: Inicial y anual | Q9: Control unificador de gobernanza. | R9: R1 normativa + R2 anexos + R3 cruce | S9: Cl. 5.3, 7.5; A.5.2 Roles y responsabilidades; A.5.3 Segregación de funciones; A.5.36 Cumplimiento; A.5.37 Procedimientos documentados | T9: =IF(K9="Cumple","Mantener / evidenciar",IF(K9="Parcial","Cerrar brecha parcial",IF(K9="No cumple","Implementar control",IF(K9="No aplica","Sin acción","Levantar evidencia")))) -> Mantener / evidenciar | U9: =IF(K9="Cumple","Mantener evidencia y revisión periódica",IF(K9="No aplica","Documentar justificación de no aplicabilidad",IF(K9="Por evaluar","Levantar evidencia y confirmar aplicabilidad",IF(K9="Parcial","Completar documentación/control y validar efectividad",IF(K9="No cumple","Diseñar, aprobar e implementar control requerido","Corregir valor de cumplimiento"))))) -> Mantener evidencia y revisión periódica | V9: =IF(K9="No cumple",IF(O9="Alta","0-30 días",IF(O9="Media","31-60 días","61-90 días")),IF(K9="Parcial",IF(O9="Alta","0-45 días",IF(O9="Media","31-75 días","61-120 días")),IF(K9="Por evaluar",IF(O9="Alta","0-15 días","0-30 días"),IF(K9="Cumple","Revisión periódica","No aplica")))) -> Revisión periódica | W9: =IF(K9="No cumple",IF(O9="Alta",3,IF(O9="Media",2,1)),IF(K9="Parcial",IF(O9="Alta",2,IF(O9="Media",1.5,1)),IF(K9="Por evaluar",IF(O9="Alta",1.5,IF(O9="Media",1,0.5)),0))) -> 0 | X9: =IF(K9="No aplica","No aplica",IF(K9="Cumple","Mantenimiento",IF(K9="Por evaluar","Fase 0 - Evidencia/aplicabilidad",IF(OR(B9="Gobernanza",B9="SGSI",B9="Contexto y alcance"),"Fase 1 - Gobierno y SGSI",IF(OR(B9="Riesgos",B9="Procesos",B9="Personas"),"Fase 2 - Riesgos y operación",IF(OR(B9="Terceros",B9="Continuidad"),"Fase 3 - Continuidad y terceros",IF(OR(B9="Tecnología",B9="Accesos",B9="Ciberseguridad",B9="Vulnerabilidades",B9="Incidentes",B9="Monitoreo"),"Fase 4 - Controles técnicos","Fase 5 - Canales y datos"))))))) -> Mantenimiento
A10: 9 | B10: Gobernanza | C10: Área de Seguridad | D10: Contar con área/unidad independiente de Seguridad de la Información | E10: SB exige área independiente y especializada que reporte a máxima autoridad gerencial, separada de negocio, tecnología, riesgos y auditoría. SEPS exige Unidad/Departamento para régimen general adscrito a Gerencia General. | F10: SEPS Art. 8; SB Art. 24 | G10: Ambas | H10: SEPS Art. 8; SB Art. 24 | I10: Organigrama aprobado, descripción de puesto, dependencia jerárquica, independencia funcional, perfil del equipo y evidencia de recursos. | J10: 1 | K10: =IF(TRIM(J10&"")="","Por evaluar",IF(UPPER(TRIM(J10&""))="N/A","No aplica",IF(OR(J10=1,J10="1"),"Cumple",IF(OR(J10=0.5,J10="0.5"),"Parcial",IF(OR(J10=0,J10="0"),"No cumple","Revisar valor"))))) -> Cumple | N10: Gerencia General / CISO | O10: Alta | P10: Inicial y ante cambios organizacionales | Q10: Independencia funcional es más explícita en SB. | R10: R1 normativa + R2 anexos + R3 cruce | S10: Cl. 5.3, 7.1; A.5.2 Roles y responsabilidades; A.5.3 Segregación de funciones; A.5.4 Responsabilidades de la dirección | T10: =IF(K10="Cumple","Mantener / evidenciar",IF(K10="Parcial","Cerrar brecha parcial",IF(K10="No cumple","Implementar control",IF(K10="No aplica","Sin acción","Levantar evidencia")))) -> Mantener / evidenciar | U10: =IF(K10="Cumple","Mantener evidencia y revisión periódica",IF(K10="No aplica","Documentar justificación de no aplicabilidad",IF(K10="Por evaluar","Levantar evidencia y confirmar aplicabilidad",IF(K10="Parcial","Completar documentación/control y validar efectividad",IF(K10="No cumple","Diseñar, aprobar e implementar control requerido","Corregir valor de cumplimiento"))))) -> Mantener evidencia y revisión periódica | V10: =IF(K10="No cumple",IF(O10="Alta","0-30 días",IF(O10="Media","31-60 días","61-90 días")),IF(K10="Parcial",IF(O10="Alta","0-45 días",IF(O10="Media","31-75 días","61-120 días")),IF(K10="Por evaluar",IF(O10="Alta","0-15 días","0-30 días"),IF(K10="Cumple","Revisión periódica","No aplica")))) -> Revisión periódica | W10: =IF(K10="No cumple",IF(O10="Alta",3,IF(O10="Media",2,1)),IF(K10="Parcial",IF(O10="Alta",2,IF(O10="Media",1.5,1)),IF(K10="Por evaluar",IF(O10="Alta",1.5,IF(O10="Media",1,0.5)),0))) -> 0 | X10: =IF(K10="No aplica","No aplica",IF(K10="Cumple","Mantenimiento",IF(K10="Por evaluar","Fase 0 - Evidencia/aplicabilidad",IF(OR(B10="Gobernanza",B10="SGSI",B10="Contexto y alcance"),"Fase 1 - Gobierno y SGSI",IF(OR(B10="Riesgos",B10="Procesos",B10="Personas"),"Fase 2 - Riesgos y operación",IF(OR(B10="Terceros",B10="Continuidad"),"Fase 3 - Continuidad y terceros",IF(OR(B10="Tecnología",B10="Accesos",B10="Ciberseguridad",B10="Vulnerabilidades",B10="Incidentes",B10="Monitoreo"),"Fase 4 - Controles técnicos","Fase 5 - Canales y datos"))))))) -> Mantenimiento
A11: 10 | B11: Gobernanza | C11: Responsable/OSI | D11: Designar Oficial o Responsable de Seguridad de la Información | E11: Debe existir un OSI/responsable con funciones de definición, supervisión, ejecución y mejora de la gestión de seguridad de la información; SEPS define requisitos de capacitación y experiencia según régimen. | F11: SEPS Art. 8, 12, 17, 20, 23, 26; SB Art. 24 | G11: Ambas | H11: SEPS y SB | I11: Nombramiento formal, perfil de cargo, hoja de vida, certificaciones/capacitaciones, matriz RACI y plan de sustitución. | J11: 1 | K11: =IF(TRIM(J11&"")="","Por evaluar",IF(UPPER(TRIM(J11&""))="N/A","No aplica",IF(OR(J11=1,J11="1"),"Cumple",IF(OR(J11=0.5,J11="0.5"),"Parcial",IF(OR(J11=0,J11="0"),"No cumple","Revisar valor"))))) -> Cumple | N11: Gerencia General | O11: Alta | P11: Inicial y ante cambios | Q11: Equivalencia OSI SEPS / responsable área SI SB. | R11: R1 normativa + R2 anexos + R3 cruce | S11: Cl. 5.3, 7.2; A.5.2 Roles y responsabilidades; A.6.3 Concienciación, educación y formación | T11: =IF(K11="Cumple","Mantener / evidenciar",IF(K11="Parcial","Cerrar brecha parcial",IF(K11="No cumple","Implementar control",IF(K11="No aplica","Sin acción","Levantar evidencia")))) -> Mantener / evidenciar | U11: =IF(K11="Cumple","Mantener evidencia y revisión periódica",IF(K11="No aplica","Documentar justificación de no aplicabilidad",IF(K11="Por evaluar","Levantar evidencia y confirmar aplicabilidad",IF(K11="Parcial","Completar documentación/control y validar efectividad",IF(K11="No cumple","Diseñar, aprobar e implementar control requerido","Corregir valor de cumplimiento"))))) -> Mantener evidencia y revisión periódica | V11: =IF(K11="No cumple",IF(O11="Alta","0-30 días",IF(O11="Media","31-60 días","61-90 días")),IF(K11="Parcial",IF(O11="Alta","0-45 días",IF(O11="Media","31-75 días","61-120 días")),IF(K11="Por evaluar",IF(O11="Alta","0-15 días","0-30 días"),IF(K11="Cumple","Revisión periódica","No aplica")))) -> Revisión periódica | W11: =IF(K11="No cumple",IF(O11="Alta",3,IF(O11="Media",2,1)),IF(K11="Parcial",IF(O11="Alta",2,IF(O11="Media",1.5,1)),IF(K11="Por evaluar",IF(O11="Alta",1.5,IF(O11="Media",1,0.5)),0))) -> 0 | X11: =IF(K11="No aplica","No aplica",IF(K11="Cumple","Mantenimiento",IF(K11="Por evaluar","Fase 0 - Evidencia/aplicabilidad",IF(OR(B11="Gobernanza",B11="SGSI",B11="Contexto y alcance"),"Fase 1 - Gobierno y SGSI",IF(OR(B11="Riesgos",B11="Procesos",B11="Personas"),"Fase 2 - Riesgos y operación",IF(OR(B11="Terceros",B11="Continuidad"),"Fase 3 - Continuidad y terceros",IF(OR(B11="Tecnología",B11="Accesos",B11="Ciberseguridad",B11="Vulnerabilidades",B11="Incidentes",B11="Monitoreo"),"Fase 4 - Controles técnicos","Fase 5 - Canales y datos"))))))) -> Mantenimiento
A12: 11 | B12: Gobernanza | C12: Recursos | D12: Asignar recursos humanos, técnicos y financieros | E12: Deben existir recursos aprobados para gestión de seguridad, controles, capacitación, riesgos, auditorías y tecnologías de seguridad. | F12: SEPS Art. 9, 18, 24; SB Art. 15, 24, 25 | G12: Ambas | H12: SEPS Art. 9/18/24; SB Art. 15/25 | I12: Plan de recursos, presupuesto anual, plan operativo, requerimientos de herramientas, personal, capacitación, consultorías y licencias. | J12: 0 | K12: =IF(TRIM(J12&"")="","Por evaluar",IF(UPPER(TRIM(J12&""))="N/A","No aplica",IF(OR(J12=1,J12="1"),"Cumple",IF(OR(J12=0.5,J12="0.5"),"Parcial",IF(OR(J12=0,J12="0"),"No cumple","Revisar valor"))))) -> No cumple | N12: Directorio / Gerencia General / CISO | O12: Alta | P12: Anual | Q12: Control habilitante para todo el programa. | R12: R1 normativa + R2 anexos + R3 cruce | S12: Cl. 7.1, 7.2; A.5.2 Roles y responsabilidades; A.6.3 Formación y concienciación | T12: =IF(K12="Cumple","Mantener / evidenciar",IF(K12="Parcial","Cerrar brecha parcial",IF(K12="No cumple","Implementar control",IF(K12="No aplica","Sin acción","Levantar evidencia")))) -> Implementar control | U12: =IF(K12="Cumple","Mantener evidencia y revisión periódica",IF(K12="No aplica","Documentar justificación de no aplicabilidad",IF(K12="Por evaluar","Levantar evidencia y confirmar aplicabilidad",IF(K12="Parcial","Completar documentación/control y validar efectividad",IF(K12="No cumple","Diseñar, aprobar e implementar control requerido","Corregir valor de cumplimiento"))))) -> Diseñar, aprobar e implementar control requerido | V12: =IF(K12="No cumple",IF(O12="Alta","0-30 días",IF(O12="Media","31-60 días","61-90 días")),IF(K12="Parcial",IF(O12="Alta","0-45 días",IF(O12="Media","31-75 días","61-120 días")),IF(K12="Por evaluar",IF(O12="Alta","0-15 días","0-30 días"),IF(K12="Cumple","Revisión periódica","No aplica")))) -> 0-30 días | W12: =IF(K12="No cumple",IF(O12="Alta",3,IF(O12="Media",2,1)),IF(K12="Parcial",IF(O12="Alta",2,IF(O12="Media",1.5,1)),IF(K12="Por evaluar",IF(O12="Alta",1.5,IF(O12="Media",1,0.5)),0))) -> 3 | X12: =IF(K12="No aplica","No aplica",IF(K12="Cumple","Mantenimiento",IF(K12="Por evaluar","Fase 0 - Evidencia/aplicabilidad",IF(OR(B12="Gobernanza",B12="SGSI",B12="Contexto y alcance"),"Fase 1 - Gobierno y SGSI",IF(OR(B12="Riesgos",B12="Procesos",B12="Personas"),"Fase 2 - Riesgos y operación",IF(OR(B12="Terceros",B12="Continuidad"),"Fase 3 - Continuidad y terceros",IF(OR(B12="Tecnología",B12="Accesos",B12="Ciberseguridad",B12="Vulnerabilidades",B12="Incidentes",B12="Monitoreo"),"Fase 4 - Controles técnicos","Fase 5 - Canales y datos"))))))) -> Fase 1 - Gobierno y SGSI
A13: 12 | B13: Gobernanza | C13: Gerencia General | D13: Liderar y promover la gestión de Seguridad de la Información | E13: La gerencia debe liderar la gestión, designar al OSI/responsable y promover la participación de partes interesadas. | F13: SEPS Art. 12, 20, 26; SB Art. 24 | G13: Ambas | H13: SEPS y SB | I13: Acta de designación, comunicaciones de patrocinio, participación en comité, matriz de stakeholders y seguimiento de recursos. | J13: 1 | K13: =IF(TRIM(J13&"")="","Por evaluar",IF(UPPER(TRIM(J13&""))="N/A","No aplica",IF(OR(J13=1,J13="1"),"Cumple",IF(OR(J13=0.5,J13="0.5"),"Parcial",IF(OR(J13=0,J13="0"),"No cumple","Revisar valor"))))) -> Cumple | M13: Generar carta de compromiso de la gerencia | N13: Gerencia General | O13: Alta | P13: Permanente | Q13: Gobierno y tone at the top. | R13: R1 normativa + R2 anexos + R3 cruce | S13: Cl. 5.1; A.5.4 Responsabilidades de la dirección; A.5.1 Políticas de SI | T13: =IF(K13="Cumple","Mantener / evidenciar",IF(K13="Parcial","Cerrar brecha parcial",IF(K13="No cumple","Implementar control",IF(K13="No aplica","Sin acción","Levantar evidencia")))) -> Mantener / evidenciar | U13: =IF(K13="Cumple","Mantener evidencia y revisión periódica",IF(K13="No aplica","Documentar justificación de no aplicabilidad",IF(K13="Por evaluar","Levantar evidencia y confirmar aplicabilidad",IF(K13="Parcial","Completar documentación/control y validar efectividad",IF(K13="No cumple","Diseñar, aprobar e implementar control requerido","Corregir valor de cumplimiento"))))) -> Mantener evidencia y revisión periódica | V13: =IF(K13="No cumple",IF(O13="Alta","0-30 días",IF(O13="Media","31-60 días","61-90 días")),IF(K13="Parcial",IF(O13="Alta","0-45 días",IF(O13="Media","31-75 días","61-120 días")),IF(K13="Por evaluar",IF(O13="Alta","0-15 días","0-30 días"),IF(K13="Cumple","Revisión periódica","No aplica")))) -> Revisión periódica | W13: =IF(K13="No cumple",IF(O13="Alta",3,IF(O13="Media",2,1)),IF(K13="Parcial",IF(O13="Alta",2,IF(O13="Media",1.5,1)),IF(K13="Por evaluar",IF(O13="Alta",1.5,IF(O13="Media",1,0.5)),0))) -> 0 | X13: =IF(K13="No aplica","No aplica",IF(K13="Cumple","Mantenimiento",IF(K13="Por evaluar","Fase 0 - Evidencia/aplicabilidad",IF(OR(B13="Gobernanza",B13="SGSI",B13="Contexto y alcance"),"Fase 1 - Gobierno y SGSI",IF(OR(B13="Riesgos",B13="Procesos",B13="Personas"),"Fase 2 - Riesgos y operación",IF(OR(B13="Terceros",B13="Continuidad"),"Fase 3 - Continuidad y terceros",IF(OR(B13="Tecnología",B13="Accesos",B13="Ciberseguridad",B13="Vulnerabilidades",B13="Incidentes",B13="Monitoreo"),"Fase 4 - Controles técnicos","Fase 5 - Canales y datos"))))))) -> Mantenimiento
A14: 13 | B14: Gobernanza | C14: Auditoría interna / vigilancia | D14: Verificar eficacia del SGSI y controles | E14: SB exige revisión periódica de efectividad del SGSI y continuidad; SEPS asigna funciones a Auditor Interno/Consejo de Vigilancia para verificar medidas, custodiar informes y recomendar correcciones. | F14: SEPS Art. 12, 20, 26; SB Art. 11 | G14: Ambas | H14: SEPS y SB | I14: Plan anual de auditoría, informes de revisión, pruebas de efectividad, evidencias de hallazgos, planes de acción y seguimiento. | J14: 0.5 | K14: =IF(TRIM(J14&"")="","Por evaluar",IF(UPPER(TRIM(J14&""))="N/A","No aplica",IF(OR(J14=1,J14="1"),"Cumple",IF(OR(J14=0.5,J14="0.5"),"Parcial",IF(OR(J14=0,J14="0"),"No cumple","Revisar valor"))))) -> Parcial | M14: En fase inicial | N14: Auditoría Interna / Consejo de Vigilancia | O14: Alta | P14: Anual y según plan | Q14: Tercera línea de defensa. | R14: R1 normativa + R2 anexos + R3 cruce | S14: Cl. 9.2, 9.3; A.5.35 Revisión independiente de SI; A.8.34 Protección durante pruebas de auditoría | T14: =IF(K14="Cumple","Mantener / evidenciar",IF(K14="Parcial","Cerrar brecha parcial",IF(K14="No cumple","Implementar control",IF(K14="No aplica","Sin acción","Levantar evidencia")))) -> Cerrar brecha parcial | U14: =IF(K14="Cumple","Mantener evidencia y revisión periódica",IF(K14="No aplica","Documentar justificación de no aplicabilidad",IF(K14="Por evaluar","Levantar evidencia y confirmar aplicabilidad",IF(K14="Parcial","Completar documentación/control y validar efectividad",IF(K14="No cumple","Diseñar, aprobar e implementar control requerido","Corregir valor de cumplimiento"))))) -> Completar documentación/control y validar efectividad | V14: =IF(K14="No cumple",IF(O14="Alta","0-30 días",IF(O14="Media","31-60 días","61-90 días")),IF(K14="Parcial",IF(O14="Alta","0-45 días",IF(O14="Media","31-75 días","61-120 días")),IF(K14="Por evaluar",IF(O14="Alta","0-15 días","0-30 días"),IF(K14="Cumple","Revisión periódica","No aplica")))) -> 0-45 días | W14: =IF(K14="No cumple",IF(O14="Alta",3,IF(O14="Media",2,1)),IF(K14="Parcial",IF(O14="Alta",2,IF(O14="Media",1.5,1)),IF(K14="Por evaluar",IF(O14="Alta",1.5,IF(O14="Media",1,0.5)),0))) -> 2 | X14: =IF(K14="No aplica","No aplica",IF(K14="Cumple","Mantenimiento",IF(K14="Por evaluar","Fase 0 - Evidencia/aplicabilidad",IF(OR(B14="Gobernanza",B14="SGSI",B14="Contexto y alcance"),"Fase 1 - Gobierno y SGSI",IF(OR(B14="Riesgos",B14="Procesos",B14="Personas"),"Fase 2 - Riesgos y operación",IF(OR(B14="Terceros",B14="Continuidad"),"Fase 3 - Continuidad y terceros",IF(OR(B14="Tecnología",B14="Accesos",B14="Ciberseguridad",B14="Vulnerabilidades",B14="Incidentes",B14="Monitoreo"),"Fase 4 - Controles técnicos","Fase 5 - Canales y datos"))))))) -> Fase 1 - Gobierno y SGSI
A15: 14 | B15: Gobernanza | C15: Revisión documental | D15: Revisar y actualizar documentación de seguridad | E15: SEPS exige revisión anual y actualización cuando corresponda; SB exige revisión anual o ante cambios significativos para políticas, metodologías y continuidad. | F15: SEPS Art. 21 y 27; SB Art. 19, 25 | G15: Ambas | H15: SEPS Art. 21/27; SB Art. 19/25 | I15: Calendario de revisión documental, control de versiones, aprobaciones, historial de cambios y evidencia de difusión. | J15: 0.5 | K15: =IF(TRIM(J15&"")="","Por evaluar",IF(UPPER(TRIM(J15&""))="N/A","No aplica",IF(OR(J15=1,J15="1"),"Cumple",IF(OR(J15=0.5,J15="0.5"),"Parcial",IF(OR(J15=0,J15="0"),"No cumple","Revisar valor"))))) -> Parcial | M15: Se va a colocar en Eramba | N15: CISO / Dueños de documentos | O15: Media | P15: Anual o ante cambios | Q15: Requisito recurrente. | R15: R1 normativa + R2 anexos + R3 cruce | S15: Cl. 7.5, 9.3, 10.1; A.5.36 Cumplimiento de políticas; A.5.37 Procedimientos operativos documentados | T15: =IF(K15="Cumple","Mantener / evidenciar",IF(K15="Parcial","Cerrar brecha parcial",IF(K15="No cumple","Implementar control",IF(K15="No aplica","Sin acción","Levantar evidencia")))) -> Cerrar brecha parcial | U15: =IF(K15="Cumple","Mantener evidencia y revisión periódica",IF(K15="No aplica","Documentar justificación de no aplicabilidad",IF(K15="Por evaluar","Levantar evidencia y confirmar aplicabilidad",IF(K15="Parcial","Completar documentación/control y validar efectividad",IF(K15="No cumple","Diseñar, aprobar e implementar control requerido","Corregir valor de cumplimiento"))))) -> Completar documentación/control y validar efectividad | V15: =IF(K15="No cumple",IF(O15="Alta","0-30 días",IF(O15="Media","31-60 días","61-90 días")),IF(K15="Parcial",IF(O15="Alta","0-45 días",IF(O15="Media","31-75 días","61-120 días")),IF(K15="Por evaluar",IF(O15="Alta","0-15 días","0-30 días"),IF(K15="Cumple","Revisión periódica","No aplica")))) -> 31-75 días | W15: =IF(K15="No cumple",IF(O15="Alta",3,IF(O15="Media",2,1)),IF(K15="Parcial",IF(O15="Alta",2,IF(O15="Media",1.5,1)),IF(K15="Por evaluar",IF(O15="Alta",1.5,IF(O15="Media",1,0.5)),0))) -> 1.5 | X15: =IF(K15="No aplica","No aplica",IF(K15="Cumple","Mantenimiento",IF(K15="Por evaluar","Fase 0 - Evidencia/aplicabilidad",IF(OR(B15="Gobernanza",B15="SGSI",B15="Contexto y alcance"),"Fase 1 - Gobierno y SGSI",IF(OR(B15="Riesgos",B15="Procesos",B15="Personas"),"Fase 2 - Riesgos y operación",IF(OR(B15="Terceros",B15="Continuidad"),"Fase 3 - Continuidad y terceros",IF(OR(B15="Tecnología",B15="Accesos",B15="Ciberseguridad",B15="Vulnerabilidades",B15="Incidentes",B15="Monitoreo"),"Fase 4 - Controles técnicos","Fase 5 - Canales y datos"))))))) -> Fase 1 - Gobierno y SGSI
A16: 15 | B16: SGSI | C16: Sistema de gestión | D16: Implementar, mantener y mejorar continuamente el SGSI | E16: Debe existir un SGSI que gestione seguridad de la información y ciberseguridad, alineado a estándares reconocidos y normativa aplicable. | F16: SEPS Art. 10; SB Art. 24-25 | G16: Ambas | H16: SEPS Art. 10; SB Art. 24-25 | I16: Manual/Modelo SGSI, alcance, política, objetivos, mapa de procesos, matriz de riesgos, controles, indicadores, auditorías y mejora continua. | J16: 0.5 | K16: =IF(TRIM(J16&"")="","Por evaluar",IF(UPPER(TRIM(J16&""))="N/A","No aplica",IF(OR(J16=1,J16="1"),"Cumple",IF(OR(J16=0.5,J16="0.5"),"Parcial",IF(OR(J16=0,J16="0"),"No cumple","Revisar valor"))))) -> Parcial | M16: Aplicabilidad de CIS Controls alineado a NIST CSF | N16: CISO | O16: Alta | P16: Permanente | Q16: Núcleo de cumplimiento. | R16: R1 normativa + R2 anexos + R3 cruce | S16: Cl. 4.4, 5.2, 6.1, 8.1, 9.1, 10.2; A.5.1 Políticas de SI | T16: =IF(K16="Cumple","Mantener / evidenciar",IF(K16="Parcial","Cerrar brecha parcial",IF(K16="No cumple","Implementar control",IF(K16="No aplica","Sin acción","Levantar evidencia")))) -> Cerrar brecha parcial | U16: =IF(K16="Cumple","Mantener evidencia y revisión periódica",IF(K16="No aplica","Documentar justificación de no aplicabilidad",IF(K16="Por evaluar","Levantar evidencia y confirmar aplicabilidad",IF(K16="Parcial","Completar documentación/control y validar efectividad",IF(K16="No cumple","Diseñar, aprobar e implementar control requerido","Corregir valor de cumplimiento"))))) -> Completar documentación/control y validar efectividad | V16: =IF(K16="No cumple",IF(O16="Alta","0-30 días",IF(O16="Media","31-60 días","61-90 días")),IF(K16="Parcial",IF(O16="Alta","0-45 días",IF(O16="Media","31-75 días","61-120 días")),IF(K16="Por evaluar",IF(O16="Alta","0-15 días","0-30 días"),IF(K16="Cumple","Revisión periódica","No aplica")))) -> 0-45 días | W16: =IF(K16="No cumple",IF(O16="Alta",3,IF(O16="Media",2,1)),IF(K16="Parcial",IF(O16="Alta",2,IF(O16="Media",1.5,1)),IF(K16="Por evaluar",IF(O16="Alta",1.5,IF(O16="Media",1,0.5)),0))) -> 2 | X16: =IF(K16="No aplica","No aplica",IF(K16="Cumple","Mantenimiento",IF(K16="Por evaluar","Fase 0 - Evidencia/aplicabilidad",IF(OR(B16="Gobernanza",B16="SGSI",B16="Contexto y alcance"),"Fase 1 - Gobierno y SGSI",IF(OR(B16="Riesgos",B16="Procesos",B16="Personas"),"Fase 2 - Riesgos y operación",IF(OR(B16="Terceros",B16="Continuidad"),"Fase 3 - Continuidad y terceros",IF(OR(B16="Tecnología",B16="Accesos",B16="Ciberseguridad",B16="Vulnerabilidades",B16="Incidentes",B16="Monitoreo"),"Fase 4 - Controles técnicos","Fase 5 - Canales y datos"))))))) -> Fase 1 - Gobierno y SGSI
A17: 16 | B17: SGSI | C17: Políticas y procedimientos | D17: Definir políticas, procesos, procedimientos, roles y responsabilidades | E17: Las normas exigen normativa interna documentada, difundida, alineada a objetivos de negocio y con consecuencias por incumplimiento. | F17: SEPS Art. 9, 18, 24; Anexo 1; SB Art. 25 | G17: Ambas | H17: SEPS Anexo 1; SB Art. 25 | I17: Política de Seguridad de la Información, procedimientos, instructivos, RACI, flujos de aprobación y registro de difusión/aceptación. | J17: 0.5 | K17: =IF(TRIM(J17&"")="","Por evaluar",IF(UPPER(TRIM(J17&""))="N/A","No aplica",IF(OR(J17=1,J17="1"),"Cumple",IF(OR(J17=0.5,J17="0.5"),"Parcial",IF(OR(J17=0,J17="0"),"No cumple","Revisar valor"))))) -> Parcial | M17: Inicial, en construcción | N17: CISO / Procesos | O17: Alta | P17: Anual | Q17: Incluye ciberseguridad en SB. | R17: R1 normativa + R2 anexos + R3 cruce | S17: Cl. 5.2, 5.3, 7.5; A.5.1 Políticas; A.5.2 Roles; A.5.36 Cumplimiento; A.5.37 Procedimientos documentados | T17: =IF(K17="Cumple","Mantener / evidenciar",IF(K17="Parcial","Cerrar brecha parcial",IF(K17="No cumple","Implementar control",IF(K17="No aplica","Sin acción","Levantar evidencia")))) -> Cerrar brecha parcial | U17: =IF(K17="Cumple","Mantener evidencia y revisión periódica",IF(K17="No aplica","Documentar justificación de no aplicabilidad",IF(K17="Por evaluar","Levantar evidencia y confirmar aplicabilidad",IF(K17="Parcial","Completar documentación/control y validar efectividad",IF(K17="No cumple","Diseñar, aprobar e implementar control requerido","Corregir valor de cumplimiento"))))) -> Completar documentación/control y validar efectividad | V17: =IF(K17="No cumple",IF(O17="Alta","0-30 días",IF(O17="Media","31-60 días","61-90 días")),IF(K17="Parcial",IF(O17="Alta","0-45 días",IF(O17="Media","31-75 días","61-120 días")),IF(K17="Por evaluar",IF(O17="Alta","0-15 días","0-30 días"),IF(K17="Cumple","Revisión periódica","No aplica")))) -> 0-45 días | W17: =IF(K17="No cumple",IF(O17="Alta",3,IF(O17="Media",2,1)),IF(K17="Parcial",IF(O17="Alta",2,IF(O17="Media",1.5,1)),IF(K17="Por evaluar",IF(O17="Alta",1.5,IF(O17="Media",1,0.5)),0))) -> 2 | X17: =IF(K17="No aplica","No aplica",IF(K17="Cumple","Mantenimiento",IF(K17="Por evaluar","Fase 0 - Evidencia/aplicabilidad",IF(OR(B17="Gobernanza",B17="SGSI",B17="Contexto y alcance"),"Fase 1 - Gobierno y SGSI",IF(OR(B17="Riesgos",B17="Procesos",B17="Personas"),"Fase 2 - Riesgos y operación",IF(OR(B17="Terceros",B17="Continuidad"),"Fase 3 - Continuidad y terceros",IF(OR(B17="Tecnología",B17="Accesos",B17="Ciberseguridad",B17="Vulnerabilidades",B17="Incidentes",B17="Monitoreo"),"Fase 4 - Controles técnicos","Fase 5 - Canales y datos"))))))) -> Fase 1 - Gobierno y SGSI
A18: 17 | B18: SGSI | C18: Plan estratégico | D18: Contar con Plan Estratégico de Seguridad de la Información | E18: SEPS régimen general exige PESI; SB exige estrategia y objetivos de SI alineados a estrategia institucional. | F18: SEPS Art. 9 y 12; SB Art. 24 | G18: Ambas | H18: SEPS Art. 9/12; SB Art. 24 | I18: PESI aprobado, objetivos, iniciativas, responsables, presupuesto, indicadores, relación con plan estratégico institucional y seguimiento. | J18: 0.5 | K18: =IF(TRIM(J18&"")="","Por evaluar",IF(UPPER(TRIM(J18&""))="N/A","No aplica",IF(OR(J18=1,J18="1"),"Cumple",IF(OR(J18=0.5,J18="0.5"),"Parcial",IF(OR(J18=0,J18="0"),"No cumple","Revisar valor"))))) -> Parcial | M18: Se tiene pero en reforma | N18: CISO / Directorio | O18: Alta | P18: Anual o plurianual con seguimiento | Q18: Unifica PESI con estrategia SB. | R18: R1 normativa + R2 anexos + R3 cruce | S18: Cl. 6.2, 6.3; A.5.1 Políticas de SI; A.5.8 Seguridad en gestión de proyectos | T18: =IF(K18="Cumple","Mantener / evidenciar",IF(K18="Parcial","Cerrar brecha parcial",IF(K18="No cumple","Implementar control",IF(K18="No aplica","Sin acción","Levantar evidencia")))) -> Cerrar brecha parcial | U18: =IF(K18="Cumple","Mantener evidencia y revisión periódica",IF(K18="No aplica","Documentar justificación de no aplicabilidad",IF(K18="Por evaluar","Levantar evidencia y confirmar aplicabilidad",IF(K18="Parcial","Completar documentación/control y validar efectividad",IF(K18="No cumple","Diseñar, aprobar e implementar control requerido","Corregir valor de cumplimiento"))))) -> Completar documentación/control y validar efectividad | V18: =IF(K18="No cumple",IF(O18="Alta","0-30 días",IF(O18="Media","31-60 días","61-90 días")),IF(K18="Parcial",IF(O18="Alta","0-45 días",IF(O18="Media","31-75 días","61-120 días")),IF(K18="Por evaluar",IF(O18="Alta","0-15 días","0-30 días"),IF(K18="Cumple","Revisión periódica","No aplica")))) -> 0-45 días | W18: =IF(K18="No cumple",IF(O18="Alta",3,IF(O18="Media",2,1)),IF(K18="Parcial",IF(O18="Alta",2,IF(O18="Media",1.5,1)),IF(K18="Por evaluar",IF(O18="Alta",1.5,IF(O18="Media",1,0.5)),0))) -> 2 | X18: =IF(K18="No aplica","No aplica",IF(K18="Cumple","Mantenimiento",IF(K18="Por evaluar","Fase 0 - Evidencia/aplicabilidad",IF(OR(B18="Gobernanza",B18="SGSI",B18="Contexto y alcance"),"Fase 1 - Gobierno y SGSI",IF(OR(B18="Riesgos",B18="Procesos",B18="Personas"),"Fase 2 - Riesgos y operación",IF(OR(B18="Terceros",B18="Continuidad"),"Fase 3 - Continuidad y terceros",IF(OR(B18="Tecnología",B18="Accesos",B18="Ciberseguridad",B18="Vulnerabilidades",B18="Incidentes",B18="Monitoreo"),"Fase 4 - Controles técnicos","Fase 5 - Canales y datos"))))))) -> Fase 1 - Gobierno y SGSI
A19: 18 | B19: SGSI | C19: Plan operativo / plan de seguridad | D19: Planificar controles y acciones de mejora | E19: El plan debe permitir implementar controles identificados, acciones de mejora y mitigación de riesgos de SI y ciberseguridad. | F19: SB Art. 25; SEPS Anexo 1 y 2 | G19: Ambas | H19: SB Art. 25; SEPS Anexo 2 | I19: Plan de seguridad de la información, cartera de controles, plan de tratamiento, cronograma, responsables, costos, estado y evidencia de cierre. | J19: 0 | K19: =IF(TRIM(J19&"")="","Por evaluar",IF(UPPER(TRIM(J19&""))="N/A","No aplica",IF(OR(J19=1,J19="1"),"Cumple",IF(OR(J19=0.5,J19="0.5"),"Parcial",IF(OR(J19=0,J19="0"),"No cumple","Revisar valor"))))) -> No cumple | M19: Fase inicial, aun no se contempla | N19: CISO | O19: Alta | P19: Trimestral seguimiento / anual planificación | Q19: Equivale a plan de tratamiento y plan de controles. | R19: R1 normativa + R2 anexos + R3 cruce | S19: Cl. 6.1, 6.2, 8.1; A.5.8 Seguridad en proyectos; A.5.36 Cumplimiento | T19: =IF(K19="Cumple","Mantener / evidenciar",IF(K19="Parcial","Cerrar brecha parcial",IF(K19="No cumple","Implementar control",IF(K19="No aplica","Sin acción","Levantar evidencia")))) -> Implementar control | U19: =IF(K19="Cumple","Mantener evidencia y revisión periódica",IF(K19="No aplica","Documentar justificación de no aplicabilidad",IF(K19="Por evaluar","Levantar evidencia y confirmar aplicabilidad",IF(K19="Parcial","Completar documentación/control y validar efectividad",IF(K19="No cumple","Diseñar, aprobar e implementar control requerido","Corregir valor de cumplimiento"))))) -> Diseñar, aprobar e implementar control requerido | V19: =IF(K19="No cumple",IF(O19="Alta","0-30 días",IF(O19="Media","31-60 días","61-90 días")),IF(K19="Parcial",IF(O19="Alta","0-45 días",IF(O19="Media","31-75 días","61-120 días")),IF(K19="Por evaluar",IF(O19="Alta","0-15 días","0-30 días"),IF(K19="Cumple","Revisión periódica","No aplica")))) -> 0-30 días | W19: =IF(K19="No cumple",IF(O19="Alta",3,IF(O19="Media",2,1)),IF(K19="Parcial",IF(O19="Alta",2,IF(O19="Media",1.5,1)),IF(K19="Por evaluar",IF(O19="Alta",1.5,IF(O19="Media",1,0.5)),0))) -> 3 | X19: =IF(K19="No aplica","No aplica",IF(K19="Cumple","Mantenimiento",IF(K19="Por evaluar","Fase 0 - Evidencia/aplicabilidad",IF(OR(B19="Gobernanza",B19="SGSI",B19="Contexto y alcance"),"Fase 1 - Gobierno y SGSI",IF(OR(B19="Riesgos",B19="Procesos",B19="Personas"),"Fase 2 - Riesgos y operación",IF(OR(B19="Terceros",B19="Continuidad"),"Fase 3 - Continuidad y terceros",IF(OR(B19="Tecnología",B19="Accesos",B19="Ciberseguridad",B19="Vulnerabilidades",B19="Incidentes",B19="Monitoreo"),"Fase 4 - Controles técnicos","Fase 5 - Canales y datos"))))))) -> Fase 1 - Gobierno y SGSI
A20: 19 | B20: SGSI | C20: Capacitación y cultura | D20: Ejecutar plan de concienciación y formación | E20: SEPS exige plan/actividades de concienciación y formación; Anexo 1 pide evaluar el plan, medir madurez y capacitar a personal, proveedores, clientes, socios y usuarios. SB exige capacitación a empleados y clientes según alcance. | F20: SEPS Art. 9, 18, 24, Anexo 1; SB Art. 25, 27 | G20: Ambas | H20: SEPS Art. 9/Anexo 1; SB Art. 25/27 | I20: Plan anual de capacitación, campañas, registros de asistencia, evaluaciones, indicadores de madurez, campañas a clientes/proveedores cuando aplique. | J20: 1 | K20: =IF(TRIM(J20&"")="","Por evaluar",IF(UPPER(TRIM(J20&""))="N/A","No aplica",IF(OR(J20=1,J20="1"),"Cumple",IF(OR(J20=0.5,J20="0.5"),"Parcial",IF(OR(J20=0,J20="0"),"No cumple","Revisar valor"))))) -> Cumple | M20: Creada campaña anual | N20: CISO / Talento Humano / Marketing | O20: Media | P20: Anual con ejecución continua | Q20: Incluye cultura interna y externa. | R20: R1 normativa + R2 anexos + R3 cruce | S20: Cl. 7.2, 7.3; A.6.3 Concienciación, educación y formación en SI | T20: =IF(K20="Cumple","Mantener / evidenciar",IF(K20="Parcial","Cerrar brecha parcial",IF(K20="No cumple","Implementar control",IF(K20="No aplica","Sin acción","Levantar evidencia")))) -> Mantener / evidenciar | U20: =IF(K20="Cumple","Mantener evidencia y revisión periódica",IF(K20="No aplica","Documentar justificación de no aplicabilidad",IF(K20="Por evaluar","Levantar evidencia y confirmar aplicabilidad",IF(K20="Parcial","Completar documentación/control y validar efectividad",IF(K20="No cumple","Diseñar, aprobar e implementar control requerido","Corregir valor de cumplimiento"))))) -> Mantener evidencia y revisión periódica | V20: =IF(K20="No cumple",IF(O20="Alta","0-30 días",IF(O20="Media","31-60 días","61-90 días")),IF(K20="Parcial",IF(O20="Alta","0-45 días",IF(O20="Media","31-75 días","61-120 días")),IF(K20="Por evaluar",IF(O20="Alta","0-15 días","0-30 días"),IF(K20="Cumple","Revisión periódica","No aplica")))) -> Revisión periódica | W20: =IF(K20="No cumple",IF(O20="Alta",3,IF(O20="Media",2,1)),IF(K20="Parcial",IF(O20="Alta",2,IF(O20="Media",1.5,1)),IF(K20="Por evaluar",IF(O20="Alta",1.5,IF(O20="Media",1,0.5)),0))) -> 0 | X20: =IF(K20="No aplica","No aplica",IF(K20="Cumple","Mantenimiento",IF(K20="Por evaluar","Fase 0 - Evidencia/aplicabilidad",IF(OR(B20="Gobernanza",B20="SGSI",B20="Contexto y alcance"),"Fase 1 - Gobierno y SGSI",IF(OR(B20="Riesgos",B20="Procesos",B20="Personas"),"Fase 2 - Riesgos y operación",IF(OR(B20="Terceros",B20="Continuidad"),"Fase 3 - Continuidad y terceros",IF(OR(B20="Tecnología",B20="Accesos",B20="Ciberseguridad",B20="Vulnerabilidades",B20="Incidentes",B20="Monitoreo"),"Fase 4 - Controles técnicos","Fase 5 - Canales y datos"))))))) -> Mantenimiento
A21: 20 | B21: SGSI | C21: Evidencia documental | D21: Generar y conservar documentación de la gestión | E21: SEPS exige que el OSI/responsable genere documentación que evidencie la gestión; SB exige evidencias de comités, informes, monitoreos, auditorías, pruebas y reportes. | F21: SEPS Art. 12, 20, 26; SB Art. 24-27 | G21: Ambas | H21: SEPS y SB | I21: Repositorio SGSI con control de versiones, evidencias por requisito, actas, informes, tickets, aprobaciones, reportes y matrices. | J21: 0 | K21: =IF(TRIM(J21&"")="","Por evaluar",IF(UPPER(TRIM(J21&""))="N/A","No aplica",IF(OR(J21=1,J21="1"),"Cumple",IF(OR(J21=0.5,J21="0.5"),"Parcial",IF(OR(J21=0,J21="0"),"No cumple","Revisar valor"))))) -> No cumple | M21: Aún no se ejecuta CSI, pero se va a ejecutar | N21: CISO / PMO / Procesos | O21: Alta | P21: Permanente | Q21: Necesario para due diligence y supervisión. | R21: R1 normativa + R2 anexos + R3 cruce | S21: Cl. 7.5; A.5.33 Protección de registros; A.5.37 Procedimientos operativos documentados | T21: =IF(K21="Cumple","Mantener / evidenciar",IF(K21="Parcial","Cerrar brecha parcial",IF(K21="No cumple","Implementar control",IF(K21="No aplica","Sin acción","Levantar evidencia")))) -> Implementar control | U21: =IF(K21="Cumple","Mantener evidencia y revisión periódica",IF(K21="No aplica","Documentar justificación de no aplicabilidad",IF(K21="Por evaluar","Levantar evidencia y confirmar aplicabilidad",IF(K21="Parcial","Completar documentación/control y validar efectividad",IF(K21="No cumple","Diseñar, aprobar e implementar control requerido","Corregir valor de cumplimiento"))))) -> Diseñar, aprobar e implementar control requerido | V21: =IF(K21="No cumple",IF(O21="Alta","0-30 días",IF(O21="Media","31-60 días","61-90 días")),IF(K21="Parcial",IF(O21="Alta","0-45 días",IF(O21="Media","31-75 días","61-120 días")),IF(K21="Por evaluar",IF(O21="Alta","0-15 días","0-30 días"),IF(K21="Cumple","Revisión periódica","No aplica")))) -> 0-30 días | W21: =IF(K21="No cumple",IF(O21="Alta",3,IF(O21="Media",2,1)),IF(K21="Parcial",IF(O21="Alta",2,IF(O21="Media",1.5,1)),IF(K21="Por evaluar",IF(O21="Alta",1.5,IF(O21="Media",1,0.5)),0))) -> 3 | X21: =IF(K21="No aplica","No aplica",IF(K21="Cumple","Mantenimiento",IF(K21="Por evaluar","Fase 0 - Evidencia/aplicabilidad",IF(OR(B21="Gobernanza",B21="SGSI",B21="Contexto y alcance"),"Fase 1 - Gobierno y SGSI",IF(OR(B21="Riesgos",B21="Procesos",B21="Personas"),"Fase 2 - Riesgos y operación",IF(OR(B21="Terceros",B21="Continuidad"),"Fase 3 - Continuidad y terceros",IF(OR(B21="Tecnología",B21="Accesos",B21="Ciberseguridad",B21="Vulnerabilidades",B21="Incidentes",B21="Monitoreo"),"Fase 4 - Controles técnicos","Fase 5 - Canales y datos"))))))) -> Fase 1 - Gobierno y SGSI
A22: 21 | B22: SGSI | C22: Políticas específicas SEPS | D22: Mantener normativa interna mínima de seguridad | E22: SEPS Anexo 1 menciona políticas/control de clasificación, gestión de riesgos, accesos físicos y tecnológicos, incidentes, software, infraestructura tecnológica, recursos humanos, seguridad física, terceros y ciberseguridad. | F22: SEPS Anexo 1, páginas controles obligatorios | G22: SEPS | H22: SEPS Anexo 1 | I22: Catálogo de políticas y procedimientos mínimos: clasificación, riesgos SI, accesos, incidentes, software, infraestructura, RRHH, seguridad física, terceros, ciberseguridad. | J22: 0.5 | K22: =IF(TRIM(J22&"")="","Por evaluar",IF(UPPER(TRIM(J22&""))="N/A","No aplica",IF(OR(J22=1,J22="1"),"Cumple",IF(OR(J22=0.5,J22="0.5"),"Parcial",IF(OR(J22=0,J22="0"),"No cumple","Revisar valor"))))) -> Parcial | M22: En elaboración, pendiente: Accesos Incidentes SW Infraestructura TTHH Seg. Física Terceros Ciberseguridad | N22: CISO / TIC / Talento Humano | O22: Alta | P22: Anual | Q22: Sin equivalente exacto como listado en SB; se cruza con Art. 25. | R22: R1 normativa + R2 anexos + R3 cruce | S22: Cl. 5.2, 7.5; A.5.1 Políticas; A.5.10 Uso aceptable; A.5.14 Transferencia de información; A.5.15 Control de acceso; A.8.13 Respaldo; A.8.24 Criptografía; A.8.32 Gestión de cambios | T22: =IF(K22="Cumple","Mantener / evidenciar",IF(K22="Parcial","Cerrar brecha parcial",IF(K22="No cumple","Implementar control",IF(K22="No aplica","Sin acción","Levantar evidencia")))) -> Cerrar brecha parcial | U22: =IF(K22="Cumple","Mantener evidencia y revisión periódica",IF(K22="No aplica","Documentar justificación de no aplicabilidad",IF(K22="Por evaluar","Levantar evidencia y confirmar aplicabilidad",IF(K22="Parcial","Completar documentación/control y validar efectividad",IF(K22="No cumple","Diseñar, aprobar e implementar control requerido","Corregir valor de cumplimiento"))))) -> Completar documentación/control y validar efectividad | V22: =IF(K22="No cumple",IF(O22="Alta","0-30 días",IF(O22="Media","31-60 días","61-90 días")),IF(K22="Parcial",IF(O22="Alta","0-45 días",IF(O22="Media","31-75 días","61-120 días")),IF(K22="Por evaluar",IF(O22="Alta","0-15 días","0-30 días"),IF(K22="Cumple","Revisión periódica","No aplica")))) -> 0-45 días | W22: =IF(K22="No cumple",IF(O22="Alta",3,IF(O22="Media",2,1)),IF(K22="Parcial",IF(O22="Alta",2,IF(O22="Media",1.5,1)),IF(K22="Por evaluar",IF(O22="Alta",1.5,IF(O22="Media",1,0.5)),0))) -> 2 | X22: =IF(K22="No aplica","No aplica",IF(K22="Cumple","Mantenimiento",IF(K22="Por evaluar","Fase 0 - Evidencia/aplicabilidad",IF(OR(B22="Gobernanza",B22="SGSI",B22="Contexto y alcance"),"Fase 1 - Gobierno y SGSI",IF(OR(B22="Riesgos",B22="Procesos",B22="Personas"),"Fase 2 - Riesgos y operación",IF(OR(B22="Terceros",B22="Continuidad"),"Fase 3 - Continuidad y terceros",IF(OR(B22="Tecnología",B22="Accesos",B22="Ciberseguridad",B22="Vulnerabilidades",B22="Incidentes",B22="Monitoreo"),"Fase 4 - Controles técnicos","Fase 5 - Canales y datos"))))))) -> Fase 1 - Gobierno y SGSI
